[2025-01-23T15:04:21.073+0000] {local_task_job_runner.py:123} INFO - ::group::Pre task execution logs
[2025-01-23T15:04:21.079+0000] {taskinstance.py:2613} INFO - Dependencies all met for dep_context=non-requeueable deps ti=<TaskInstance: data_ingestion_premise_postgres_dag.download_dataset_task scheduled__2025-01-22T00:00:00+00:00 [queued]>
[2025-01-23T15:04:21.081+0000] {taskinstance.py:2613} INFO - Dependencies all met for dep_context=requeueable deps ti=<TaskInstance: data_ingestion_premise_postgres_dag.download_dataset_task scheduled__2025-01-22T00:00:00+00:00 [queued]>
[2025-01-23T15:04:21.081+0000] {taskinstance.py:2866} INFO - Starting attempt 1 of 2
[2025-01-23T15:04:21.085+0000] {taskinstance.py:2889} INFO - Executing <Task(BashOperator): download_dataset_task> on 2025-01-22 00:00:00+00:00
[2025-01-23T15:04:21.087+0000] {warnings.py:112} WARNING - /home/***/.local/lib/python3.12/site-packages/***/task/task_runner/standard_task_runner.py:70: DeprecationWarning: This process (pid=197) is multi-threaded, use of fork() may lead to deadlocks in the child.
  pid = os.fork()

[2025-01-23T15:04:21.088+0000] {standard_task_runner.py:72} INFO - Started process 202 to run task
[2025-01-23T15:04:21.089+0000] {standard_task_runner.py:104} INFO - Running: ['***', 'tasks', 'run', 'data_ingestion_premise_postgres_dag', 'download_dataset_task', 'scheduled__2025-01-22T00:00:00+00:00', '--job-id', '7', '--raw', '--subdir', 'DAGS_FOLDER/Premise Project/ingest_data_to_local_postgres.py', '--cfg-path', '/tmp/tmpqjbgwjn2']
[2025-01-23T15:04:21.090+0000] {standard_task_runner.py:105} INFO - Job 7: Subtask download_dataset_task
[2025-01-23T15:04:21.108+0000] {task_command.py:467} INFO - Running <TaskInstance: data_ingestion_premise_postgres_dag.download_dataset_task scheduled__2025-01-22T00:00:00+00:00 [running]> on host ba1a11192658
[2025-01-23T15:04:21.368+0000] {taskinstance.py:3132} INFO - Exporting env vars: AIRFLOW_CTX_DAG_OWNER='***' AIRFLOW_CTX_DAG_ID='data_ingestion_premise_postgres_dag' AIRFLOW_CTX_TASK_ID='download_dataset_task' AIRFLOW_CTX_EXECUTION_DATE='2025-01-22T00:00:00+00:00' AIRFLOW_CTX_TRY_NUMBER='1' AIRFLOW_CTX_DAG_RUN_ID='scheduled__2025-01-22T00:00:00+00:00'
[2025-01-23T15:04:21.369+0000] {taskinstance.py:731} INFO - ::endgroup::
[2025-01-23T15:04:21.375+0000] {subprocess.py:78} INFO - Tmp dir root location: /tmp
[2025-01-23T15:04:21.376+0000] {subprocess.py:88} INFO - Running command: ['/usr/bin/bash', '-c', 'curl -sS -L --fail https://github.com/DataTalksClub/nyc-tlc-data/releases/download/yellow/yellow_tripdata_2021-01.csv.gz > /opt/***/yellow_tripdata_2021-01.csv.gz']
[2025-01-23T15:04:21.382+0000] {subprocess.py:99} INFO - Output:
[2025-01-23T15:10:25.746+0000] {subprocess.py:106} INFO - curl: (18) HTTP/2 stream 1 was not closed cleanly before end of the underlying stream
[2025-01-23T15:10:25.753+0000] {subprocess.py:110} INFO - Command exited with return code 18
[2025-01-23T15:10:25.775+0000] {taskinstance.py:3311} ERROR - Task failed with exception
Traceback (most recent call last):
  File "/home/airflow/.local/lib/python3.12/site-packages/airflow/models/taskinstance.py", line 767, in _execute_task
    result = _execute_callable(context=context, **execute_callable_kwargs)
             ^^^^^^^^^^^^^^^^^^^^^^^^^^^^^^^^^^^^^^^^^^^^^^^^^^^^^^^^^^^^^
  File "/home/airflow/.local/lib/python3.12/site-packages/airflow/models/taskinstance.py", line 733, in _execute_callable
    return ExecutionCallableRunner(
           ^^^^^^^^^^^^^^^^^^^^^^^^
  File "/home/airflow/.local/lib/python3.12/site-packages/airflow/utils/operator_helpers.py", line 252, in run
    return self.func(*args, **kwargs)
           ^^^^^^^^^^^^^^^^^^^^^^^^^^
  File "/home/airflow/.local/lib/python3.12/site-packages/airflow/models/baseoperator.py", line 422, in wrapper
    return func(self, *args, **kwargs)
           ^^^^^^^^^^^^^^^^^^^^^^^^^^^
  File "/home/airflow/.local/lib/python3.12/site-packages/airflow/operators/bash.py", line 276, in execute
    raise AirflowException(
airflow.exceptions.AirflowException: Bash command failed. The command returned a non-zero exit code 18.
[2025-01-23T15:10:25.792+0000] {taskinstance.py:1225} INFO - Marking task as UP_FOR_RETRY. dag_id=data_ingestion_premise_postgres_dag, task_id=download_dataset_task, run_id=scheduled__2025-01-22T00:00:00+00:00, execution_date=20250122T000000, start_date=20250123T150421, end_date=20250123T151025
[2025-01-23T15:10:25.806+0000] {taskinstance.py:340} INFO - ::group::Post task execution logs
[2025-01-23T15:10:25.806+0000] {standard_task_runner.py:124} ERROR - Failed to execute job 7 for task download_dataset_task (Bash command failed. The command returned a non-zero exit code 18.; 202)
Traceback (most recent call last):
  File "/home/airflow/.local/lib/python3.12/site-packages/airflow/task/task_runner/standard_task_runner.py", line 117, in _start_by_fork
    ret = args.func(args, dag=self.dag)
          ^^^^^^^^^^^^^^^^^^^^^^^^^^^^^
  File "/home/airflow/.local/lib/python3.12/site-packages/airflow/cli/cli_config.py", line 49, in command
    return func(*args, **kwargs)
           ^^^^^^^^^^^^^^^^^^^^^
  File "/home/airflow/.local/lib/python3.12/site-packages/airflow/utils/cli.py", line 116, in wrapper
    return f(*args, **kwargs)
           ^^^^^^^^^^^^^^^^^^
  File "/home/airflow/.local/lib/python3.12/site-packages/airflow/cli/commands/task_command.py", line 483, in task_run
    task_return_code = _run_task_by_selected_method(args, _dag, ti)
                       ^^^^^^^^^^^^^^^^^^^^^^^^^^^^^^^^^^^^^^^^^^^^
  File "/home/airflow/.local/lib/python3.12/site-packages/airflow/cli/commands/task_command.py", line 256, in _run_task_by_selected_method
    return _run_raw_task(args, ti)
           ^^^^^^^^^^^^^^^^^^^^^^^
  File "/home/airflow/.local/lib/python3.12/site-packages/airflow/cli/commands/task_command.py", line 341, in _run_raw_task
    return ti._run_raw_task(
           ^^^^^^^^^^^^^^^^^
  File "/home/airflow/.local/lib/python3.12/site-packages/airflow/utils/session.py", line 97, in wrapper
    return func(*args, session=session, **kwargs)
           ^^^^^^^^^^^^^^^^^^^^^^^^^^^^^^^^^^^^^^
  File "/home/airflow/.local/lib/python3.12/site-packages/airflow/models/taskinstance.py", line 3005, in _run_raw_task
    return _run_raw_task(
           ^^^^^^^^^^^^^^
  File "/home/airflow/.local/lib/python3.12/site-packages/airflow/models/taskinstance.py", line 273, in _run_raw_task
    TaskInstance._execute_task_with_callbacks(
  File "/home/airflow/.local/lib/python3.12/site-packages/airflow/models/taskinstance.py", line 3159, in _execute_task_with_callbacks
    result = self._execute_task(context, task_orig)
             ^^^^^^^^^^^^^^^^^^^^^^^^^^^^^^^^^^^^^^
  File "/home/airflow/.local/lib/python3.12/site-packages/airflow/models/taskinstance.py", line 3183, in _execute_task
    return _execute_task(self, context, task_orig)
           ^^^^^^^^^^^^^^^^^^^^^^^^^^^^^^^^^^^^^^^
  File "/home/airflow/.local/lib/python3.12/site-packages/airflow/models/taskinstance.py", line 767, in _execute_task
    result = _execute_callable(context=context, **execute_callable_kwargs)
             ^^^^^^^^^^^^^^^^^^^^^^^^^^^^^^^^^^^^^^^^^^^^^^^^^^^^^^^^^^^^^
  File "/home/airflow/.local/lib/python3.12/site-packages/airflow/models/taskinstance.py", line 733, in _execute_callable
    return ExecutionCallableRunner(
           ^^^^^^^^^^^^^^^^^^^^^^^^
  File "/home/airflow/.local/lib/python3.12/site-packages/airflow/utils/operator_helpers.py", line 252, in run
    return self.func(*args, **kwargs)
           ^^^^^^^^^^^^^^^^^^^^^^^^^^
  File "/home/airflow/.local/lib/python3.12/site-packages/airflow/models/baseoperator.py", line 422, in wrapper
    return func(self, *args, **kwargs)
           ^^^^^^^^^^^^^^^^^^^^^^^^^^^
  File "/home/airflow/.local/lib/python3.12/site-packages/airflow/operators/bash.py", line 276, in execute
    raise AirflowException(
airflow.exceptions.AirflowException: Bash command failed. The command returned a non-zero exit code 18.
[2025-01-23T15:10:25.835+0000] {local_task_job_runner.py:266} INFO - Task exited with return code 1
[2025-01-23T15:10:26.068+0000] {taskinstance.py:3895} INFO - 0 downstream tasks scheduled from follow-on schedule check
[2025-01-23T15:10:26.069+0000] {local_task_job_runner.py:245} INFO - ::endgroup::
