[2025-01-24T04:08:16.810+0000] {local_task_job_runner.py:123} INFO - ::group::Pre task execution logs
[2025-01-24T04:08:16.815+0000] {taskinstance.py:2613} INFO - Dependencies all met for dep_context=non-requeueable deps ti=<TaskInstance: data_ingestion_gcs_dag.local_to_gcs_task manual__2025-01-24T04:02:40.417396+00:00 [queued]>
[2025-01-24T04:08:16.817+0000] {taskinstance.py:2613} INFO - Dependencies all met for dep_context=requeueable deps ti=<TaskInstance: data_ingestion_gcs_dag.local_to_gcs_task manual__2025-01-24T04:02:40.417396+00:00 [queued]>
[2025-01-24T04:08:16.818+0000] {taskinstance.py:2866} INFO - Starting attempt 1 of 2
[2025-01-24T04:08:16.822+0000] {taskinstance.py:2889} INFO - Executing <Task(PythonOperator): local_to_gcs_task> on 2025-01-24 04:02:40.417396+00:00
[2025-01-24T04:08:16.824+0000] {warnings.py:112} WARNING - /home/***/.local/lib/python3.12/site-packages/***/task/task_runner/standard_task_runner.py:70: DeprecationWarning: This process (pid=195) is multi-threaded, use of fork() may lead to deadlocks in the child.
  pid = os.fork()

[2025-01-24T04:08:16.825+0000] {standard_task_runner.py:72} INFO - Started process 196 to run task
[2025-01-24T04:08:16.825+0000] {standard_task_runner.py:104} INFO - Running: ['***', 'tasks', 'run', 'data_ingestion_gcs_dag', 'local_to_gcs_task', 'manual__2025-01-24T04:02:40.417396+00:00', '--job-id', '28', '--raw', '--subdir', 'DAGS_FOLDER/GCP Project/data_ingestion_gcs_dag.py', '--cfg-path', '/tmp/tmpr29srrps']
[2025-01-24T04:08:16.827+0000] {standard_task_runner.py:105} INFO - Job 28: Subtask local_to_gcs_task
[2025-01-24T04:08:16.841+0000] {task_command.py:467} INFO - Running <TaskInstance: data_ingestion_gcs_dag.local_to_gcs_task manual__2025-01-24T04:02:40.417396+00:00 [running]> on host 3d9406b7dd3e
[2025-01-24T04:08:16.863+0000] {taskinstance.py:3132} INFO - Exporting env vars: AIRFLOW_CTX_DAG_OWNER='***' AIRFLOW_CTX_DAG_ID='data_ingestion_gcs_dag' AIRFLOW_CTX_TASK_ID='local_to_gcs_task' AIRFLOW_CTX_EXECUTION_DATE='2025-01-24T04:02:40.417396+00:00' AIRFLOW_CTX_TRY_NUMBER='1' AIRFLOW_CTX_DAG_RUN_ID='manual__2025-01-24T04:02:40.417396+00:00'
[2025-01-24T04:08:16.863+0000] {taskinstance.py:731} INFO - ::endgroup::
[2025-01-24T04:08:16.876+0000] {_default.py:340} WARNING - Authentication failed using Compute Engine authentication due to unavailable metadata server.
[2025-01-24T04:08:16.876+0000] {taskinstance.py:3311} ERROR - Task failed with exception
Traceback (most recent call last):
  File "/home/airflow/.local/lib/python3.12/site-packages/airflow/models/taskinstance.py", line 767, in _execute_task
    result = _execute_callable(context=context, **execute_callable_kwargs)
             ^^^^^^^^^^^^^^^^^^^^^^^^^^^^^^^^^^^^^^^^^^^^^^^^^^^^^^^^^^^^^
  File "/home/airflow/.local/lib/python3.12/site-packages/airflow/models/taskinstance.py", line 733, in _execute_callable
    return ExecutionCallableRunner(
           ^^^^^^^^^^^^^^^^^^^^^^^^
  File "/home/airflow/.local/lib/python3.12/site-packages/airflow/utils/operator_helpers.py", line 252, in run
    return self.func(*args, **kwargs)
           ^^^^^^^^^^^^^^^^^^^^^^^^^^
  File "/home/airflow/.local/lib/python3.12/site-packages/airflow/models/baseoperator.py", line 422, in wrapper
    return func(self, *args, **kwargs)
           ^^^^^^^^^^^^^^^^^^^^^^^^^^^
  File "/home/airflow/.local/lib/python3.12/site-packages/airflow/operators/python.py", line 238, in execute
    return_value = self.execute_callable()
                   ^^^^^^^^^^^^^^^^^^^^^^^
  File "/home/airflow/.local/lib/python3.12/site-packages/airflow/operators/python.py", line 256, in execute_callable
    return runner.run(*self.op_args, **self.op_kwargs)
           ^^^^^^^^^^^^^^^^^^^^^^^^^^^^^^^^^^^^^^^^^^^
  File "/home/airflow/.local/lib/python3.12/site-packages/airflow/utils/operator_helpers.py", line 252, in run
    return self.func(*args, **kwargs)
           ^^^^^^^^^^^^^^^^^^^^^^^^^^
  File "/opt/airflow/dags/GCP Project/data_ingestion_gcs_dag.py", line 90, in upload_to_gcs
    client = storage.Client()                # 创建Storage客户端
             ^^^^^^^^^^^^^^^^
  File "/home/airflow/.local/lib/python3.12/site-packages/google/cloud/storage/client.py", line 228, in __init__
    super(Client, self).__init__(
  File "/home/airflow/.local/lib/python3.12/site-packages/google/cloud/client/__init__.py", line 320, in __init__
    _ClientProjectMixin.__init__(self, project=project, credentials=credentials)
  File "/home/airflow/.local/lib/python3.12/site-packages/google/cloud/client/__init__.py", line 268, in __init__
    project = self._determine_default(project)
              ^^^^^^^^^^^^^^^^^^^^^^^^^^^^^^^^
  File "/home/airflow/.local/lib/python3.12/site-packages/google/cloud/client/__init__.py", line 287, in _determine_default
    return _determine_default_project(project)
           ^^^^^^^^^^^^^^^^^^^^^^^^^^^^^^^^^^^
  File "/home/airflow/.local/lib/python3.12/site-packages/google/cloud/_helpers/__init__.py", line 152, in _determine_default_project
    _, project = google.auth.default()
                 ^^^^^^^^^^^^^^^^^^^^^
  File "/home/airflow/.local/lib/python3.12/site-packages/google/auth/_default.py", line 697, in default
    raise exceptions.DefaultCredentialsError(_CLOUD_SDK_MISSING_CREDENTIALS)
google.auth.exceptions.DefaultCredentialsError: Your default credentials were not found. To set up Application Default Credentials, see https://cloud.google.com/docs/authentication/external/set-up-adc for more information.
[2025-01-24T04:08:16.881+0000] {taskinstance.py:1225} INFO - Marking task as UP_FOR_RETRY. dag_id=data_ingestion_gcs_dag, task_id=local_to_gcs_task, run_id=manual__2025-01-24T04:02:40.417396+00:00, execution_date=20250124T040240, start_date=20250124T040816, end_date=20250124T040816
[2025-01-24T04:08:16.886+0000] {taskinstance.py:340} INFO - ::group::Post task execution logs
[2025-01-24T04:08:16.886+0000] {standard_task_runner.py:124} ERROR - Failed to execute job 28 for task local_to_gcs_task (Your default credentials were not found. To set up Application Default Credentials, see https://cloud.google.com/docs/authentication/external/set-up-adc for more information.; 196)
Traceback (most recent call last):
  File "/home/airflow/.local/lib/python3.12/site-packages/airflow/task/task_runner/standard_task_runner.py", line 117, in _start_by_fork
    ret = args.func(args, dag=self.dag)
          ^^^^^^^^^^^^^^^^^^^^^^^^^^^^^
  File "/home/airflow/.local/lib/python3.12/site-packages/airflow/cli/cli_config.py", line 49, in command
    return func(*args, **kwargs)
           ^^^^^^^^^^^^^^^^^^^^^
  File "/home/airflow/.local/lib/python3.12/site-packages/airflow/utils/cli.py", line 116, in wrapper
    return f(*args, **kwargs)
           ^^^^^^^^^^^^^^^^^^
  File "/home/airflow/.local/lib/python3.12/site-packages/airflow/cli/commands/task_command.py", line 483, in task_run
    task_return_code = _run_task_by_selected_method(args, _dag, ti)
                       ^^^^^^^^^^^^^^^^^^^^^^^^^^^^^^^^^^^^^^^^^^^^
  File "/home/airflow/.local/lib/python3.12/site-packages/airflow/cli/commands/task_command.py", line 256, in _run_task_by_selected_method
    return _run_raw_task(args, ti)
           ^^^^^^^^^^^^^^^^^^^^^^^
  File "/home/airflow/.local/lib/python3.12/site-packages/airflow/cli/commands/task_command.py", line 341, in _run_raw_task
    return ti._run_raw_task(
           ^^^^^^^^^^^^^^^^^
  File "/home/airflow/.local/lib/python3.12/site-packages/airflow/utils/session.py", line 97, in wrapper
    return func(*args, session=session, **kwargs)
           ^^^^^^^^^^^^^^^^^^^^^^^^^^^^^^^^^^^^^^
  File "/home/airflow/.local/lib/python3.12/site-packages/airflow/models/taskinstance.py", line 3005, in _run_raw_task
    return _run_raw_task(
           ^^^^^^^^^^^^^^
  File "/home/airflow/.local/lib/python3.12/site-packages/airflow/models/taskinstance.py", line 273, in _run_raw_task
    TaskInstance._execute_task_with_callbacks(
  File "/home/airflow/.local/lib/python3.12/site-packages/airflow/models/taskinstance.py", line 3159, in _execute_task_with_callbacks
    result = self._execute_task(context, task_orig)
             ^^^^^^^^^^^^^^^^^^^^^^^^^^^^^^^^^^^^^^
  File "/home/airflow/.local/lib/python3.12/site-packages/airflow/models/taskinstance.py", line 3183, in _execute_task
    return _execute_task(self, context, task_orig)
           ^^^^^^^^^^^^^^^^^^^^^^^^^^^^^^^^^^^^^^^
  File "/home/airflow/.local/lib/python3.12/site-packages/airflow/models/taskinstance.py", line 767, in _execute_task
    result = _execute_callable(context=context, **execute_callable_kwargs)
             ^^^^^^^^^^^^^^^^^^^^^^^^^^^^^^^^^^^^^^^^^^^^^^^^^^^^^^^^^^^^^
  File "/home/airflow/.local/lib/python3.12/site-packages/airflow/models/taskinstance.py", line 733, in _execute_callable
    return ExecutionCallableRunner(
           ^^^^^^^^^^^^^^^^^^^^^^^^
  File "/home/airflow/.local/lib/python3.12/site-packages/airflow/utils/operator_helpers.py", line 252, in run
    return self.func(*args, **kwargs)
           ^^^^^^^^^^^^^^^^^^^^^^^^^^
  File "/home/airflow/.local/lib/python3.12/site-packages/airflow/models/baseoperator.py", line 422, in wrapper
    return func(self, *args, **kwargs)
           ^^^^^^^^^^^^^^^^^^^^^^^^^^^
  File "/home/airflow/.local/lib/python3.12/site-packages/airflow/operators/python.py", line 238, in execute
    return_value = self.execute_callable()
                   ^^^^^^^^^^^^^^^^^^^^^^^
  File "/home/airflow/.local/lib/python3.12/site-packages/airflow/operators/python.py", line 256, in execute_callable
    return runner.run(*self.op_args, **self.op_kwargs)
           ^^^^^^^^^^^^^^^^^^^^^^^^^^^^^^^^^^^^^^^^^^^
  File "/home/airflow/.local/lib/python3.12/site-packages/airflow/utils/operator_helpers.py", line 252, in run
    return self.func(*args, **kwargs)
           ^^^^^^^^^^^^^^^^^^^^^^^^^^
  File "/opt/airflow/dags/GCP Project/data_ingestion_gcs_dag.py", line 90, in upload_to_gcs
    client = storage.Client()                # 创建Storage客户端
             ^^^^^^^^^^^^^^^^
  File "/home/airflow/.local/lib/python3.12/site-packages/google/cloud/storage/client.py", line 228, in __init__
    super(Client, self).__init__(
  File "/home/airflow/.local/lib/python3.12/site-packages/google/cloud/client/__init__.py", line 320, in __init__
    _ClientProjectMixin.__init__(self, project=project, credentials=credentials)
  File "/home/airflow/.local/lib/python3.12/site-packages/google/cloud/client/__init__.py", line 268, in __init__
    project = self._determine_default(project)
              ^^^^^^^^^^^^^^^^^^^^^^^^^^^^^^^^
  File "/home/airflow/.local/lib/python3.12/site-packages/google/cloud/client/__init__.py", line 287, in _determine_default
    return _determine_default_project(project)
           ^^^^^^^^^^^^^^^^^^^^^^^^^^^^^^^^^^^
  File "/home/airflow/.local/lib/python3.12/site-packages/google/cloud/_helpers/__init__.py", line 152, in _determine_default_project
    _, project = google.auth.default()
                 ^^^^^^^^^^^^^^^^^^^^^
  File "/home/airflow/.local/lib/python3.12/site-packages/google/auth/_default.py", line 697, in default
    raise exceptions.DefaultCredentialsError(_CLOUD_SDK_MISSING_CREDENTIALS)
google.auth.exceptions.DefaultCredentialsError: Your default credentials were not found. To set up Application Default Credentials, see https://cloud.google.com/docs/authentication/external/set-up-adc for more information.
[2025-01-24T04:08:16.925+0000] {local_task_job_runner.py:266} INFO - Task exited with return code 1
[2025-01-24T04:08:16.935+0000] {taskinstance.py:3895} INFO - 0 downstream tasks scheduled from follow-on schedule check
[2025-01-24T04:08:16.936+0000] {local_task_job_runner.py:245} INFO - ::endgroup::
