[2025-01-24T08:06:48.223+0000] {local_task_job_runner.py:123} INFO - ::group::Pre task execution logs
[2025-01-24T08:06:48.229+0000] {taskinstance.py:2613} INFO - Dependencies all met for dep_context=non-requeueable deps ti=<TaskInstance: data_ingestion_gcs_dag.bigquery_external_table_task_yellow_tripdata_2021-04.csv manual__2025-01-24T07:49:06.490024+00:00 [queued]>
[2025-01-24T08:06:48.232+0000] {taskinstance.py:2613} INFO - Dependencies all met for dep_context=requeueable deps ti=<TaskInstance: data_ingestion_gcs_dag.bigquery_external_table_task_yellow_tripdata_2021-04.csv manual__2025-01-24T07:49:06.490024+00:00 [queued]>
[2025-01-24T08:06:48.233+0000] {taskinstance.py:2866} INFO - Starting attempt 2 of 2
[2025-01-24T08:06:48.236+0000] {taskinstance.py:2889} INFO - Executing <Task(BigQueryCreateExternalTableOperator): bigquery_external_table_task_yellow_tripdata_2021-04.csv> on 2025-01-24 07:49:06.490024+00:00
[2025-01-24T08:06:48.240+0000] {warnings.py:112} WARNING - /home/***/.local/lib/python3.12/site-packages/***/task/task_runner/standard_task_runner.py:70: DeprecationWarning: This process (pid=278) is multi-threaded, use of fork() may lead to deadlocks in the child.
  pid = os.fork()

[2025-01-24T08:06:48.242+0000] {standard_task_runner.py:72} INFO - Started process 279 to run task
[2025-01-24T08:06:48.242+0000] {standard_task_runner.py:104} INFO - Running: ['***', 'tasks', 'run', 'data_ingestion_gcs_dag', 'bigquery_external_table_task_yellow_tripdata_2021-04.csv', 'manual__2025-01-24T07:49:06.490024+00:00', '--job-id', '74', '--raw', '--subdir', 'DAGS_FOLDER/GCP Project/data_ingestion_gcs_dag.py', '--cfg-path', '/tmp/tmp8s4bx9mz']
[2025-01-24T08:06:48.243+0000] {standard_task_runner.py:105} INFO - Job 74: Subtask bigquery_external_table_task_yellow_tripdata_2021-04.csv
[2025-01-24T08:06:48.264+0000] {task_command.py:467} INFO - Running <TaskInstance: data_ingestion_gcs_dag.bigquery_external_table_task_yellow_tripdata_2021-04.csv manual__2025-01-24T07:49:06.490024+00:00 [running]> on host 7526bafc575d
[2025-01-24T08:06:48.289+0000] {taskinstance.py:3132} INFO - Exporting env vars: AIRFLOW_CTX_DAG_OWNER='***' AIRFLOW_CTX_DAG_ID='data_ingestion_gcs_dag' AIRFLOW_CTX_TASK_ID='bigquery_external_table_task_yellow_tripdata_2021-04.csv' AIRFLOW_CTX_EXECUTION_DATE='2025-01-24T07:49:06.490024+00:00' AIRFLOW_CTX_TRY_NUMBER='2' AIRFLOW_CTX_DAG_RUN_ID='manual__2025-01-24T07:49:06.490024+00:00'
[2025-01-24T08:06:48.291+0000] {taskinstance.py:731} INFO - ::endgroup::
[2025-01-24T08:06:48.313+0000] {connection.py:277} WARNING - Connection schemes (type: google_cloud_platform) shall not contain '_' according to RFC3986.
[2025-01-24T08:06:48.314+0000] {base.py:84} INFO - Retrieving connection 'google_cloud_default'
[2025-01-24T08:06:48.314+0000] {credentials_provider.py:402} INFO - Getting connection using `google.auth.default()` since no explicit credentials are provided.
[2025-01-24T08:06:49.664+0000] {taskinstance.py:3311} ERROR - Task failed with exception
Traceback (most recent call last):
  File "/home/airflow/.local/lib/python3.12/site-packages/airflow/models/taskinstance.py", line 767, in _execute_task
    result = _execute_callable(context=context, **execute_callable_kwargs)
             ^^^^^^^^^^^^^^^^^^^^^^^^^^^^^^^^^^^^^^^^^^^^^^^^^^^^^^^^^^^^^
  File "/home/airflow/.local/lib/python3.12/site-packages/airflow/models/taskinstance.py", line 733, in _execute_callable
    return ExecutionCallableRunner(
           ^^^^^^^^^^^^^^^^^^^^^^^^
  File "/home/airflow/.local/lib/python3.12/site-packages/airflow/utils/operator_helpers.py", line 252, in run
    return self.func(*args, **kwargs)
           ^^^^^^^^^^^^^^^^^^^^^^^^^^
  File "/home/airflow/.local/lib/python3.12/site-packages/airflow/models/baseoperator.py", line 422, in wrapper
    return func(self, *args, **kwargs)
           ^^^^^^^^^^^^^^^^^^^^^^^^^^^
  File "/home/airflow/.local/lib/python3.12/site-packages/airflow/providers/google/cloud/operators/bigquery.py", line 1635, in execute
    table = bq_hook.create_empty_table(
            ^^^^^^^^^^^^^^^^^^^^^^^^^^^
  File "/home/airflow/.local/lib/python3.12/site-packages/airflow/providers/google/common/hooks/base_google.py", line 553, in inner_wrapper
    return func(self, *args, **kwargs)
           ^^^^^^^^^^^^^^^^^^^^^^^^^^^
  File "/home/airflow/.local/lib/python3.12/site-packages/airflow/providers/google/cloud/hooks/bigquery.py", line 457, in create_empty_table
    return self.get_client(project_id=project_id, location=location).create_table(
           ^^^^^^^^^^^^^^^^^^^^^^^^^^^^^^^^^^^^^^^^^^^^^^^^^^^^^^^^^^^^^^^^^^^^^^^
  File "/home/airflow/.local/lib/python3.12/site-packages/google/cloud/bigquery/client.py", line 797, in create_table
    api_response = self._call_api(
                   ^^^^^^^^^^^^^^^
  File "/home/airflow/.local/lib/python3.12/site-packages/google/cloud/bigquery/client.py", line 831, in _call_api
    return call()
           ^^^^^^
  File "/home/airflow/.local/lib/python3.12/site-packages/google/api_core/retry/retry_unary.py", line 293, in retry_wrapped_func
    return retry_target(
           ^^^^^^^^^^^^^
  File "/home/airflow/.local/lib/python3.12/site-packages/google/api_core/retry/retry_unary.py", line 153, in retry_target
    _retry_error_helper(
  File "/home/airflow/.local/lib/python3.12/site-packages/google/api_core/retry/retry_base.py", line 212, in _retry_error_helper
    raise final_exc from source_exc
  File "/home/airflow/.local/lib/python3.12/site-packages/google/api_core/retry/retry_unary.py", line 144, in retry_target
    result = target()
             ^^^^^^^^
  File "/home/airflow/.local/lib/python3.12/site-packages/google/cloud/_http/__init__.py", line 494, in api_request
    raise exceptions.from_http_response(response)
google.api_core.exceptions.Forbidden: 403 POST https://bigquery.googleapis.com/bigquery/v2/projects/de-project-prd/datasets/trips_data_all/tables?prettyPrint=false: Access Denied: Dataset de-project-prd:trips_data_all: Permission bigquery.tables.create denied on dataset de-project-prd:trips_data_all (or it may not exist).
[2025-01-24T08:06:49.676+0000] {taskinstance.py:1225} INFO - Marking task as FAILED. dag_id=data_ingestion_gcs_dag, task_id=bigquery_external_table_task_yellow_tripdata_2021-04.csv, run_id=manual__2025-01-24T07:49:06.490024+00:00, execution_date=20250124T074906, start_date=20250124T080648, end_date=20250124T080649
[2025-01-24T08:06:49.685+0000] {taskinstance.py:340} INFO - ::group::Post task execution logs
[2025-01-24T08:06:49.686+0000] {standard_task_runner.py:124} ERROR - Failed to execute job 74 for task bigquery_external_table_task_yellow_tripdata_2021-04.csv (403 POST https://bigquery.googleapis.com/bigquery/v2/projects/de-project-prd/datasets/trips_data_all/tables?prettyPrint=false: Access Denied: Dataset de-project-prd:trips_data_all: Permission bigquery.tables.create denied on dataset de-project-prd:trips_data_all (or it may not exist).; 279)
Traceback (most recent call last):
  File "/home/airflow/.local/lib/python3.12/site-packages/airflow/task/task_runner/standard_task_runner.py", line 117, in _start_by_fork
    ret = args.func(args, dag=self.dag)
          ^^^^^^^^^^^^^^^^^^^^^^^^^^^^^
  File "/home/airflow/.local/lib/python3.12/site-packages/airflow/cli/cli_config.py", line 49, in command
    return func(*args, **kwargs)
           ^^^^^^^^^^^^^^^^^^^^^
  File "/home/airflow/.local/lib/python3.12/site-packages/airflow/utils/cli.py", line 116, in wrapper
    return f(*args, **kwargs)
           ^^^^^^^^^^^^^^^^^^
  File "/home/airflow/.local/lib/python3.12/site-packages/airflow/cli/commands/task_command.py", line 483, in task_run
    task_return_code = _run_task_by_selected_method(args, _dag, ti)
                       ^^^^^^^^^^^^^^^^^^^^^^^^^^^^^^^^^^^^^^^^^^^^
  File "/home/airflow/.local/lib/python3.12/site-packages/airflow/cli/commands/task_command.py", line 256, in _run_task_by_selected_method
    return _run_raw_task(args, ti)
           ^^^^^^^^^^^^^^^^^^^^^^^
  File "/home/airflow/.local/lib/python3.12/site-packages/airflow/cli/commands/task_command.py", line 341, in _run_raw_task
    return ti._run_raw_task(
           ^^^^^^^^^^^^^^^^^
  File "/home/airflow/.local/lib/python3.12/site-packages/airflow/utils/session.py", line 97, in wrapper
    return func(*args, session=session, **kwargs)
           ^^^^^^^^^^^^^^^^^^^^^^^^^^^^^^^^^^^^^^
  File "/home/airflow/.local/lib/python3.12/site-packages/airflow/models/taskinstance.py", line 3005, in _run_raw_task
    return _run_raw_task(
           ^^^^^^^^^^^^^^
  File "/home/airflow/.local/lib/python3.12/site-packages/airflow/models/taskinstance.py", line 273, in _run_raw_task
    TaskInstance._execute_task_with_callbacks(
  File "/home/airflow/.local/lib/python3.12/site-packages/airflow/models/taskinstance.py", line 3159, in _execute_task_with_callbacks
    result = self._execute_task(context, task_orig)
             ^^^^^^^^^^^^^^^^^^^^^^^^^^^^^^^^^^^^^^
  File "/home/airflow/.local/lib/python3.12/site-packages/airflow/models/taskinstance.py", line 3183, in _execute_task
    return _execute_task(self, context, task_orig)
           ^^^^^^^^^^^^^^^^^^^^^^^^^^^^^^^^^^^^^^^
  File "/home/airflow/.local/lib/python3.12/site-packages/airflow/models/taskinstance.py", line 767, in _execute_task
    result = _execute_callable(context=context, **execute_callable_kwargs)
             ^^^^^^^^^^^^^^^^^^^^^^^^^^^^^^^^^^^^^^^^^^^^^^^^^^^^^^^^^^^^^
  File "/home/airflow/.local/lib/python3.12/site-packages/airflow/models/taskinstance.py", line 733, in _execute_callable
    return ExecutionCallableRunner(
           ^^^^^^^^^^^^^^^^^^^^^^^^
  File "/home/airflow/.local/lib/python3.12/site-packages/airflow/utils/operator_helpers.py", line 252, in run
    return self.func(*args, **kwargs)
           ^^^^^^^^^^^^^^^^^^^^^^^^^^
  File "/home/airflow/.local/lib/python3.12/site-packages/airflow/models/baseoperator.py", line 422, in wrapper
    return func(self, *args, **kwargs)
           ^^^^^^^^^^^^^^^^^^^^^^^^^^^
  File "/home/airflow/.local/lib/python3.12/site-packages/airflow/providers/google/cloud/operators/bigquery.py", line 1635, in execute
    table = bq_hook.create_empty_table(
            ^^^^^^^^^^^^^^^^^^^^^^^^^^^
  File "/home/airflow/.local/lib/python3.12/site-packages/airflow/providers/google/common/hooks/base_google.py", line 553, in inner_wrapper
    return func(self, *args, **kwargs)
           ^^^^^^^^^^^^^^^^^^^^^^^^^^^
  File "/home/airflow/.local/lib/python3.12/site-packages/airflow/providers/google/cloud/hooks/bigquery.py", line 457, in create_empty_table
    return self.get_client(project_id=project_id, location=location).create_table(
           ^^^^^^^^^^^^^^^^^^^^^^^^^^^^^^^^^^^^^^^^^^^^^^^^^^^^^^^^^^^^^^^^^^^^^^^
  File "/home/airflow/.local/lib/python3.12/site-packages/google/cloud/bigquery/client.py", line 797, in create_table
    api_response = self._call_api(
                   ^^^^^^^^^^^^^^^
  File "/home/airflow/.local/lib/python3.12/site-packages/google/cloud/bigquery/client.py", line 831, in _call_api
    return call()
           ^^^^^^
  File "/home/airflow/.local/lib/python3.12/site-packages/google/api_core/retry/retry_unary.py", line 293, in retry_wrapped_func
    return retry_target(
           ^^^^^^^^^^^^^
  File "/home/airflow/.local/lib/python3.12/site-packages/google/api_core/retry/retry_unary.py", line 153, in retry_target
    _retry_error_helper(
  File "/home/airflow/.local/lib/python3.12/site-packages/google/api_core/retry/retry_base.py", line 212, in _retry_error_helper
    raise final_exc from source_exc
  File "/home/airflow/.local/lib/python3.12/site-packages/google/api_core/retry/retry_unary.py", line 144, in retry_target
    result = target()
             ^^^^^^^^
  File "/home/airflow/.local/lib/python3.12/site-packages/google/cloud/_http/__init__.py", line 494, in api_request
    raise exceptions.from_http_response(response)
google.api_core.exceptions.Forbidden: 403 POST https://bigquery.googleapis.com/bigquery/v2/projects/de-project-prd/datasets/trips_data_all/tables?prettyPrint=false: Access Denied: Dataset de-project-prd:trips_data_all: Permission bigquery.tables.create denied on dataset de-project-prd:trips_data_all (or it may not exist).
[2025-01-24T08:06:49.696+0000] {local_task_job_runner.py:266} INFO - Task exited with return code 1
[2025-01-24T08:06:49.705+0000] {taskinstance.py:3895} INFO - 0 downstream tasks scheduled from follow-on schedule check
[2025-01-24T08:06:49.706+0000] {local_task_job_runner.py:245} INFO - ::endgroup::
